<mujoco xmlns:xacro="http://www.ros.org/wiki/xacro" model="furuta_pendulum">

    <xacro:property name="mass" value="10" />
    <xacro:property name="r"    value="0.2" />
    <xacro:property name="h"    value="1.5" />

    <xacro:property name="Z_Inertia"    value="${(1/2)*(mass)*(r**2)}" />
    <xacro:property name="X_Y_Inertia"  value="${(1/12)*mass*((3*(r**2)) + (h**2))}" />

    <compiler angle="degree"/>
    
    <asset>
        <texture builtin="checker" height="100" name="texplane" rgb1="0 0 0" rgb2="0.8 0.8 0.8" type="2d" width="100"/>
        <material name="MatPlane" reflectance="0.5" shininess="1" specular="1" texrepeat="2 2" texture="texplane"/>
    </asset>

    <option integrator="RK4" iterations="50" solver="PGS" timestep="0.003" >
        <!-- <flags solverstat="enable" energy="enable"/>-->
    </option>

    <worldbody>
        <light cutoff="100" diffuse="1 1 1" dir="-0 0 -1.3" directional="true" exponent="1" pos="0 0 1.3" specular=".1 .1 .1"/>
        <geom condim="3" friction="1 .1 .1" material="MatPlane" name="floor" pos="0 0 0" rgba="0.8 0.9 0.8 1" size="1 1 0.125" type="plane"/>
  
        <body name="suport" pos="0 0 3" >
            <geom type="cylinder" rgba="1 0 0 1" size="1 .5" mass="100"/>

            <body name="haste_horizontal" pos="1.5 0 .75" axisangle="0 1 0 90">
                <geom name="haste_horizontal_geom" type="cylinder" rgba="0 1 0 1" size=".2 1.5" mass="10"/>
                <inertial pos="0 0 0" mass="${mass}" diaginertia="${X_Y_Inertia} ${X_Y_Inertia} ${Z_Inertia}"/>

                <joint name="motor" pos="0 0 -1.5" type="hinge" axis="1 0 0"/>

                <!-- <body name="haste_vertical" pos="-1.5 0 1.71" axisangle="0 1 0 90">
                    <geom name="haste_vertical_geom" type="cylinder" rgba="0 0 1 1" size=".2 1.5" mass="10"/>
                    <inertial pos="0 0 0" mass="${mass}" diaginertia="${X_Y_Inertia} ${X_Y_Inertia} ${Z_Inertia}"/>

                    <joint name="conector" pos="0 0 1.5" limited="false" type="hinge" axis="1 0 0"/>

                </body> -->
            </body>
        </body>
    </worldbody>

    <actuator>
        <motor name="motor"  joint="motor"/>
        <!-- <motor name="conector"  joint="conector"/> -->
    </actuator>

</mujoco>